[2024-03-27 19:31:18,046: INFO/MainProcess] Connected to redis://redis:6379/0
[2024-03-27 19:31:18,049: INFO/MainProcess] mingle: searching for neighbors
[2024-03-27 19:31:19,058: INFO/MainProcess] mingle: all alone
[2024-03-27 19:31:19,068: INFO/MainProcess] celery@419b9cf7ca6d ready.
[2024-03-27 19:31:22,734: INFO/MainProcess] Events of group {task} enabled by remote.
[2024-03-27 19:47:49,578: CRITICAL/MainProcess] Unrecoverable error: ImproperlyConfigured('You need to install the pymongo library to use the MongoDB backend.')
Traceback (most recent call last):
  File "/usr/local/lib/python3.11/site-packages/celery/app/base.py", line 1250, in backend
    return self._local.backend
           ^^^^^^^^^^^^^^^^^^^
AttributeError: '_thread._local' object has no attribute 'backend'

During handling of the above exception, another exception occurred:

Traceback (most recent call last):
  File "/usr/local/lib/python3.11/site-packages/celery/worker/worker.py", line 203, in start
    self.blueprint.start(self)
  File "/usr/local/lib/python3.11/site-packages/celery/bootsteps.py", line 112, in start
    self.on_start()
  File "/usr/local/lib/python3.11/site-packages/celery/apps/worker.py", line 136, in on_start
    self.emit_banner()
  File "/usr/local/lib/python3.11/site-packages/celery/apps/worker.py", line 170, in emit_banner
    ' \n', self.startup_info(artlines=not use_image))),
           ^^^^^^^^^^^^^^^^^^^^^^^^^^^^^^^^^^^^^^^^^
  File "/usr/local/lib/python3.11/site-packages/celery/apps/worker.py", line 232, in startup_info
    results=self.app.backend.as_uri(),
            ^^^^^^^^^^^^^^^^
  File "/usr/local/lib/python3.11/site-packages/celery/app/base.py", line 1252, in backend
    self._local.backend = new_backend = self._get_backend()
                                        ^^^^^^^^^^^^^^^^^^^
  File "/usr/local/lib/python3.11/site-packages/celery/app/base.py", line 958, in _get_backend
    return backend(app=self, url=url)
           ^^^^^^^^^^^^^^^^^^^^^^^^^^
  File "/usr/local/lib/python3.11/site-packages/celery/backends/mongodb.py", line 64, in __init__
    raise ImproperlyConfigured(
celery.exceptions.ImproperlyConfigured: You need to install the pymongo library to use the MongoDB backend.
[2024-03-27 19:49:34,135: CRITICAL/MainProcess] Unrecoverable error: ImproperlyConfigured('You need to install the pymongo library to use the MongoDB backend.')
Traceback (most recent call last):
  File "/usr/local/lib/python3.11/site-packages/celery/app/base.py", line 1250, in backend
    return self._local.backend
           ^^^^^^^^^^^^^^^^^^^
AttributeError: '_thread._local' object has no attribute 'backend'

During handling of the above exception, another exception occurred:

Traceback (most recent call last):
  File "/usr/local/lib/python3.11/site-packages/celery/worker/worker.py", line 203, in start
    self.blueprint.start(self)
  File "/usr/local/lib/python3.11/site-packages/celery/bootsteps.py", line 112, in start
    self.on_start()
  File "/usr/local/lib/python3.11/site-packages/celery/apps/worker.py", line 136, in on_start
    self.emit_banner()
  File "/usr/local/lib/python3.11/site-packages/celery/apps/worker.py", line 170, in emit_banner
    ' \n', self.startup_info(artlines=not use_image))),
           ^^^^^^^^^^^^^^^^^^^^^^^^^^^^^^^^^^^^^^^^^
  File "/usr/local/lib/python3.11/site-packages/celery/apps/worker.py", line 232, in startup_info
    results=self.app.backend.as_uri(),
            ^^^^^^^^^^^^^^^^
  File "/usr/local/lib/python3.11/site-packages/celery/app/base.py", line 1252, in backend
    self._local.backend = new_backend = self._get_backend()
                                        ^^^^^^^^^^^^^^^^^^^
  File "/usr/local/lib/python3.11/site-packages/celery/app/base.py", line 958, in _get_backend
    return backend(app=self, url=url)
           ^^^^^^^^^^^^^^^^^^^^^^^^^^
  File "/usr/local/lib/python3.11/site-packages/celery/backends/mongodb.py", line 64, in __init__
    raise ImproperlyConfigured(
celery.exceptions.ImproperlyConfigured: You need to install the pymongo library to use the MongoDB backend.
[2024-03-27 19:51:40,975: ERROR/MainProcess] consumer: Cannot connect to amqp://guest:**@rabbitmq:5672//: [Errno 111] Connection refused.
Trying again in 2.00 seconds... (1/100)

[2024-03-27 19:51:42,977: ERROR/MainProcess] consumer: Cannot connect to amqp://guest:**@rabbitmq:5672//: [Errno 111] Connection refused.
Trying again in 4.00 seconds... (2/100)

[2024-03-27 19:51:46,979: ERROR/MainProcess] consumer: Cannot connect to amqp://guest:**@rabbitmq:5672//: [Errno 111] Connection refused.
Trying again in 6.00 seconds... (3/100)

[2024-03-27 19:51:52,985: INFO/MainProcess] Connected to amqp://guest:**@rabbitmq:5672//
[2024-03-27 19:51:52,989: INFO/MainProcess] mingle: searching for neighbors
[2024-03-27 19:51:54,007: INFO/MainProcess] mingle: all alone
[2024-03-27 19:51:54,030: INFO/MainProcess] celery@5903c250a269 ready.
[2024-03-27 19:51:54,222: INFO/MainProcess] Task create_task[d53b400d-0e3c-4c76-afda-5ed3eaf5a712] received
[2024-03-27 19:51:55,338: INFO/MainProcess] Events of group {task} enabled by remote.
[2024-03-27 19:52:04,234: INFO/ForkPoolWorker-7] Task create_task[d53b400d-0e3c-4c76-afda-5ed3eaf5a712] succeeded in 10.010650460000079s: True
[2024-03-27 19:53:42,055: INFO/MainProcess] Task create_task[201017f0-79ad-4241-824f-97e309fe1740] received
[2024-03-27 19:54:02,057: INFO/ForkPoolWorker-7] Task create_task[201017f0-79ad-4241-824f-97e309fe1740] succeeded in 20.001085828999976s: True
[2024-03-27 19:59:23,762: INFO/MainProcess] Task create_task[08036d9b-e384-4b16-bd1a-3f1e2ae7678e] received
[2024-03-27 19:59:33,764: INFO/ForkPoolWorker-7] Task create_task[08036d9b-e384-4b16-bd1a-3f1e2ae7678e] succeeded in 10.00117086299997s: True
[2024-03-27 20:06:19,192: ERROR/MainProcess] consumer: Cannot connect to amqp://guest:**@rabbitmq:5672//: [Errno 111] Connection refused.
Trying again in 2.00 seconds... (1/100)

[2024-03-27 20:06:21,195: ERROR/MainProcess] consumer: Cannot connect to amqp://guest:**@rabbitmq:5672//: [Errno 111] Connection refused.
Trying again in 4.00 seconds... (2/100)

[2024-03-27 20:06:25,196: ERROR/MainProcess] consumer: Cannot connect to amqp://guest:**@rabbitmq:5672//: [Errno 111] Connection refused.
Trying again in 6.00 seconds... (3/100)

[2024-03-27 20:06:31,201: INFO/MainProcess] Connected to amqp://guest:**@rabbitmq:5672//
[2024-03-27 20:06:31,205: INFO/MainProcess] mingle: searching for neighbors
[2024-03-27 20:06:32,220: INFO/MainProcess] mingle: all alone
[2024-03-27 20:06:32,245: INFO/MainProcess] celery@928c8de6ca3e ready.
[2024-03-27 20:06:33,631: INFO/MainProcess] Events of group {task} enabled by remote.
[2024-03-27 20:09:34,949: ERROR/MainProcess] consumer: Cannot connect to amqp://guest:**@rabbitmq:5672//: [Errno 111] Connection refused.
Trying again in 2.00 seconds... (1/100)

[2024-03-27 20:09:36,951: ERROR/MainProcess] consumer: Cannot connect to amqp://guest:**@rabbitmq:5672//: [Errno 111] Connection refused.
Trying again in 4.00 seconds... (2/100)

[2024-03-27 20:09:40,953: ERROR/MainProcess] consumer: Cannot connect to amqp://guest:**@rabbitmq:5672//: [Errno 111] Connection refused.
Trying again in 6.00 seconds... (3/100)

[2024-03-27 20:09:46,955: ERROR/MainProcess] consumer: Cannot connect to amqp://guest:**@rabbitmq:5672//: [Errno 111] Connection refused.
Trying again in 8.00 seconds... (4/100)

[2024-03-27 20:09:54,961: INFO/MainProcess] Connected to amqp://guest:**@rabbitmq:5672//
[2024-03-27 20:09:54,967: INFO/MainProcess] mingle: searching for neighbors
[2024-03-27 20:09:55,991: INFO/MainProcess] mingle: all alone
[2024-03-27 20:09:56,015: INFO/MainProcess] celery@36ab8205bf43 ready.
[2024-03-27 20:09:59,269: INFO/MainProcess] Events of group {task} enabled by remote.
[2024-03-27 20:10:45,535: INFO/MainProcess] Task create_task[157b55c4-0eaf-4676-aa51-699eb010c433] received
[2024-03-27 20:10:55,550: INFO/ForkPoolWorker-7] Task create_task[157b55c4-0eaf-4676-aa51-699eb010c433] succeeded in 10.014012811000157s: True
[2024-03-27 20:11:52,349: INFO/MainProcess] Task create_task[37701d83-8926-40b4-a7ea-d1bb594090b7] received
[2024-03-27 20:12:02,353: INFO/ForkPoolWorker-7] Task create_task[37701d83-8926-40b4-a7ea-d1bb594090b7] succeeded in 10.002260813000248s: True
[2024-03-27 20:13:02,842: INFO/MainProcess] Task create_task[c467c1f8-c4cd-4180-b4d0-8699e651db1e] received
[2024-03-27 20:13:02,983: INFO/MainProcess] Task create_task[9bca1294-60a0-452c-b791-16acb6a5fd8b] received
[2024-03-27 20:13:03,109: INFO/MainProcess] Task create_task[b6b597e5-a26f-4c34-bfd9-7e76d0b929c8] received
[2024-03-27 20:13:03,228: INFO/MainProcess] Task create_task[e1243632-8f59-495c-8f58-39b559b79554] received
[2024-03-27 20:13:03,350: INFO/MainProcess] Task create_task[7fb5d733-584c-4e79-8657-fb855bdd0f86] received
[2024-03-27 20:13:03,473: INFO/MainProcess] Task create_task[8c55ee74-60bf-4535-89e6-541b2aa9e5dc] received
[2024-03-27 20:13:03,608: INFO/MainProcess] Task create_task[53c079ab-1eaf-4206-8432-e988db371525] received
[2024-03-27 20:13:03,744: INFO/MainProcess] Task create_task[c3ef9bbc-c234-4461-8cb8-f3cd8980e67f] received
[2024-03-27 20:13:03,872: INFO/MainProcess] Task create_task[715d0e0e-eed9-456d-92c4-96f723ac21b6] received
[2024-03-27 20:13:22,844: INFO/ForkPoolWorker-7] Task create_task[c467c1f8-c4cd-4180-b4d0-8699e651db1e] succeeded in 20.001214126999912s: True
[2024-03-27 20:13:22,995: INFO/ForkPoolWorker-8] Task create_task[9bca1294-60a0-452c-b791-16acb6a5fd8b] succeeded in 20.010383314000137s: True
[2024-03-27 20:13:23,121: INFO/ForkPoolWorker-1] Task create_task[b6b597e5-a26f-4c34-bfd9-7e76d0b929c8] succeeded in 20.010382177000338s: True
[2024-03-27 20:13:23,240: INFO/ForkPoolWorker-9] Task create_task[e1243632-8f59-495c-8f58-39b559b79554] succeeded in 20.01063644199985s: True
[2024-03-27 20:13:23,362: INFO/ForkPoolWorker-2] Task create_task[7fb5d733-584c-4e79-8657-fb855bdd0f86] succeeded in 20.01081390599984s: True
[2024-03-27 20:13:23,485: INFO/ForkPoolWorker-10] Task create_task[8c55ee74-60bf-4535-89e6-541b2aa9e5dc] succeeded in 20.01065527000037s: True
[2024-03-27 20:13:23,620: INFO/ForkPoolWorker-3] Task create_task[53c079ab-1eaf-4206-8432-e988db371525] succeeded in 20.01046764399962s: True
[2024-03-27 20:13:23,760: INFO/ForkPoolWorker-11] Task create_task[c3ef9bbc-c234-4461-8cb8-f3cd8980e67f] succeeded in 20.014705806000165s: True
[2024-03-27 20:13:23,884: INFO/ForkPoolWorker-4] Task create_task[715d0e0e-eed9-456d-92c4-96f723ac21b6] succeeded in 20.010710050999933s: True
